Workbook

Sheet Start Here
B2: MONTHLY EXPENSE TRACKER
B3: See the whole month — together. • by Maple Money Hacks
B4: Track daily on your phone. Review monthly on one page.
B6: THE 3-STEP RITUAL
B7: 1 • CAPTURE DAILY (30 seconds) — Track every expense, every day, in any expense-manager app on your phone. Use the same category names as this sheet so month-end takes minutes, not detective work.
B8: 2 • TOTAL MONTHLY (10 minutes) — At month-end, open the Monthly Budget sheet, set the Year, and drop each category's monthly total into the matching yellow cell. Income goes at the top; savings and investing count as money out, because they left your spending account.
B9: 3 • REVIEW TOGETHER (20 minutes) — Open Month-End Review with your partner. It totals money in, money out and what you kept, and names your three biggest expense categories automatically.
B11: YOUR 20-MINUTE MONEY DATE
B12: • What was our biggest category — and was it worth it?
B13: • What is ONE thing we will trim next month? Pick one, write it in the review sheet, and stop there.
B14: • What is ONE win? A bill you lowered, a category you tamed, money you actually saved. Write that down too.
B15: • No blame, no line-by-line audit. The goal is one calm look at the whole month, then close the sheet until next month.
... B29: © Maple Money Hacks — Licensed for personal household use only. Not for resale or redistribution.

Sheet Monthly Budget
B2: MONTHLY EXPENSE TRACKER
B3: Maple Money Hacks • Daily totals in your app — monthly totals here • All amounts in CAD
B4: Year: | D4: Type the year once. Yellow cells are monthly totals from your expense app; pale green cells calculate themselves. | P4: Notes
B5: Category | C5: JAN | D5: FEB | E5: MAR | F5: APR | G5: MAY | H5: JUN | I5: JUL | J5: AUG | K5: SEP | L5: OCT | M5: NOV | N5: DEC | O5: YEAR | P5: Notes
B6: INCOME | C6: JAN | D6: FEB | E6: MAR | F6: APR | G6: MAY | H6: JUN | I6: JUL | J6: AUG | K6: SEP | L6: OCT | M6: NOV | N6: DEC | O6: YEAR
B7: Wages & salary | O7: =SUM(C7:N7) -> 0
B8: Interest & dividends | O8: =SUM(C8:N8) -> 0
B9: Other income | O9: =SUM(C9:N9) -> 0
B10: Total income | C10: =SUM(C7:C9) -> 0 | D10: =SUM(D7:D9) -> 0 | E10: =SUM(E7:E9) -> 0 | F10: =SUM(F7:F9) -> 0 | G10: =SUM(G7:G9) -> 0 | H10: =SUM(H7:H9) -> 0 | I10: =SUM(I7:I9) -> 0 | J10: =SUM(J7:J9) -> 0 | ... O10: =SUM(O7:O9) -> 0
B12: HOME | C12: JAN | D12: FEB | E12: MAR | F12: APR | G12: MAY | H12: JUN | I12: JUL | J12: AUG | K12: SEP | L12: OCT | M12: NOV | N12: DEC | O12: YEAR
B13: Rent or mortgage | O13: =SUM(C13:N13) -> 0
B14: Home or renters insurance | O14: =SUM(C14:N14) -> 0
B15: Phone bills | O15: =SUM(C15:N15) -> 0
B16: Utilities | O16: =SUM(C16:N16) -> 0 | P16: Hydro, water, heating
B17: Total — Home | C17: =SUM(C13:C16) -> 0 | D17: =SUM(D13:D16) -> 0 | E17: =SUM(E13:E16) -> 0 | F17: =SUM(F13:F16) -> 0 | G17: =SUM(G13:G16) -> 0 | H17: =SUM(H13:H16) -> 0 | I17: =SUM(I13:I16) -> 0 | J17: =SUM(J13:J16) -> 0 | ... O17: =SUM(O13:O16) -> 0
B19: DAILY LIVING | C19: JAN | D19: FEB | E19: MAR | F19: APR | G19: MAY | H19: JUN | I19: JUL | J19: AUG | K19: SEP | L19: OCT | M19: NOV | N19: DEC | O19: YEAR
B20: Groceries | O20: =SUM(C20:N20) -> 0
B21: Child care | O21: =SUM(C21:N21) -> 0
B22: Dry cleaning & laundry | O22: =SUM(C22:N22) -> 0
B23: Dining out | O23: =SUM(C23:N23) -> 0
B24: Housecleaning service | O24: =SUM(C24:N24) -> 0
B25: Pet care | O25: =SUM(C25:N25) -> 0 | P25: Food, grooming, walking
B26: Total — Daily Living | C26: =SUM(C20:C25) -> 0 | D26: =SUM(D20:D25) -> 0 | E26: =SUM(E20:E25) -> 0 | F26: =SUM(F20:F25) -> 0 | G26: =SUM(G20:G25) -> 0 | H26: =SUM(H20:H25) -> 0 | I26: =SUM(I20:I25) -> 0 | J26: =SUM(J20:J25) -> 0 | ... O26: =SUM(O20:O25) -> 0
B28: TRANSPORTATION | C28: JAN | D28: FEB | E28: MAR | F28: APR | G28: MAY | H28: JUN | I28: JUL | J28: AUG | K28: SEP | L28: OCT | M28: NOV | N28: DEC | O28: YEAR
B29: Gas & fuel | O29: =SUM(C29:N29) -> 0
B30: Vehicle insurance | O30: =SUM(C30:N30) -> 0
B31: Car payment | O31: =SUM(C31:N31) -> 0
B32: Car wash & detailing | O32: =SUM(C32:N32) -> 0
B33: Parking & repairs | O33: =SUM(C33:N33) -> 0
B34: Public transportation | O34: =SUM(C34:N34) -> 0
B35: Total — Transportation | C35: =SUM(C29:C34) -> 0 | D35: =SUM(D29:D34) -> 0 | E35: =SUM(E29:E34) -> 0 | F35: =SUM(F29:F34) -> 0 | G35: =SUM(G29:G34) -> 0 | H35: =SUM(H29:H34) -> 0 | I35: =SUM(I29:I34) -> 0 | J35: =SUM(J29:J34) -> 0 | ... O35: =SUM(O29:O34) -> 0
B37: ENTERTAINMENT | C37: JAN | D37: FEB | E37: MAR | F37: APR | G37: MAY | H37: JUN | I37: JUL | J37: AUG | K37: SEP | L37: OCT | M37: NOV | N37: DEC | O37: YEAR
B38: Cable & streaming TV | O38: =SUM(C38:N38) -> 0
B39: Movie rentals & apps | O39: =SUM(C39:N39) -> 0
B40: Movies & theatre | O40: =SUM(C40:N40) -> 0
B41: Concerts & clubs | O41: =SUM(C41:N41) -> 0
B42: Total — Entertainment | C42: =SUM(C38:C41) -> 0 | D42: =SUM(D38:D41) -> 0 | E42: =SUM(E38:E41) -> 0 | F42: =SUM(F38:F41) -> 0 | G42: =SUM(G38:G41) -> 0 | H42: =SUM(H38:H41) -> 0 | I42: =SUM(I38:I41) -> 0 | J42: =SUM(J38:J41) -> 0 | ... O42: =SUM(O38:O41) -> 0
B44: HEALTH | C44: JAN | D44: FEB | E44: MAR | F44: APR | G44: MAY | H44: JUN | I44: JUL | J44: AUG | K44: SEP | L44: OCT | M44: NOV | N44: DEC | O44: YEAR
B45: Health club dues | O45: =SUM(C45:N45) -> 0
B46: Health insurance | O46: =SUM(C46:N46) -> 0
...

Sheet Month-End Review
B2: MONTH-END REVIEW — YOUR 20-MINUTE MONEY DATE
B3: Everything calculates from the Monthly Budget sheet. Your only job: read the Top 3 together, then write ONE thing to trim and ONE win.
B4: Month | C4: Total in | D4: Total out | E4: Saved | F4: Savings rate | G4: Largest category | H4: Amount | I4: 2nd largest | J4: Amount | K4: 3rd largest | L4: Amount | M4: One thing to trim | N4: One win
B5: Jan | C5: ='Monthly Budget'!C10 -> 0 | D5: ='Monthly Budget'!C110 -> 0 | E5: =C5-D5 -> 0 | F5: =IF(C5=0,0,E5/C5) -> 0 | G5: =IF($D5=0,"—",IF(INDEX(C$21:C$32,MATCH(LARGE(C$36:C$47,1),C$36:C$47,0))=0,"—",INDEX($B$21:$B$32,MATCH(LARGE(C$36:C$47,1),C$36:C$47,0)))) -> — | H5: =IF($D5=0,0,INDEX(C$21:C$32,MATCH(LARGE(C$36:C$47,1),C$36:C$47,0))) -> 0 | I5: =IF($D5=0,"—",IF(INDEX(C$21:C$32,MATCH(LARGE(C$36:C$47,2),C$36:C$47,0))=0,"—",INDEX($B$21:$B$32,MATCH(LARGE(C$36:C$47,2),C$36:C$47,0)))) -> — | J5: =IF($D5=0,0,INDEX(C$21:C$32,MATCH(LARGE(C$36:C$47,2),C$36:C$47,0))) -> 0 | K5: =IF($D5=0,"—",IF(INDEX(C$21:C$32,MATCH(LARGE(C$36:C$47,3),C$36:C$47,0))=0,"—",INDEX($B$21:$B$32,MATCH(LARGE(C$36:C$47,3),C$36:C$47,0)))) -> — | L5: =IF($D5=0,0,INDEX(C$21:C$32,MATCH(LARGE(C$36:C$47,3),C$36:C$47,0))) -> 0
B6: Feb | C6: ='Monthly Budget'!D10 -> 0 | D6: ='Monthly Budget'!D110 -> 0 | E6: =C6-D6 -> 0 | F6: =IF(C6=0,0,E6/C6) -> 0 | G6: =IF($D6=0,"—",IF(INDEX(D$21:D$32,MATCH(LARGE(D$36:D$47,1),D$36:D$47,0))=0,"—",INDEX($B$21:$B$32,MATCH(LARGE(D$36:D$47,1),D$36:D$47,0)))) -> — | H6: =IF($D6=0,0,INDEX(D$21:D$32,MATCH(LARGE(D$36:D$47,1),D$36:D$47,0))) -> 0 | I6: =IF($D6=0,"—",IF(INDEX(D$21:D$32,MATCH(LARGE(D$36:D$47,2),D$36:D$47,0))=0,"—",INDEX($B$21:$B$32,MATCH(LARGE(D$36:D$47,2),D$36:D$47,0)))) -> — | J6: =IF($D6=0,0,INDEX(D$21:D$32,MATCH(LARGE(D$36:D$47,2),D$36:D$47,0))) -> 0 | K6: =IF($D6=0,"—",IF(INDEX(D$21:D$32,MATCH(LARGE(D$36:D$47,3),D$36:D$47,0))=0,"—",INDEX($B$21:$B$32,MATCH(LARGE(D$36:D$47,3),D$36:D$47,0)))) -> — | L6: =IF($D6=0,0,INDEX(D$21:D$32,MATCH(LARGE(D$36:D$47,3),D$36:D$47,0))) -> 0
B7: Mar | C7: ='Monthly Budget'!E10 -> 0 | D7: ='Monthly Budget'!E110 -> 0 | E7: =C7-D7 -> 0 | F7: =IF(C7=0,0,E7/C7) -> 0 | G7: =IF($D7=0,"—",IF(INDEX(E$21:E$32,MATCH(LARGE(E$36:E$47,1),E$36:E$47,0))=0,"—",INDEX($B$21:$B$32,MATCH(LARGE(E$36:E$47,1),E$36:E$47,0)))) -> — | H7: =IF($D7=0,0,INDEX(E$21:E$32,MATCH(LARGE(E$36:E$47,1),E$36:E$47,0))) -> 0 | I7: =IF($D7=0,"—",IF(INDEX(E$21:E$32,MATCH(LARGE(E$36:E$47,2),E$36:E$47,0))=0,"—",INDEX($B$21:$B$32,MATCH(LARGE(E$36:E$47,2),E$36:E$47,0)))) -> — | J7: =IF($D7=0,0,INDEX(E$21:E$32,MATCH(LARGE(E$36:E$47,2),E$36:E$47,0))) -> 0 | K7: =IF($D7=0,"—",IF(INDEX(E$21:E$32,MATCH(LARGE(E$36:E$47,3),E$36:E$47,0))=0,"—",INDEX($B$21:$B$32,MATCH(LARGE(E$36:E$47,3),E$36:E$47,0)))) -> — | L7: =IF($D7=0,0,INDEX(E$21:E$32,MATCH(LARGE(E$36:E$47,3),E$36:E$47,0))) -> 0
B8: Apr | C8: ='Monthly Budget'!F10 -> 0 | D8: ='Monthly Budget'!F110 -> 0 | E8: =C8-D8 -> 0 | F8: =IF(C8=0,0,E8/C8) -> 0 | G8: =IF($D8=0,"—",IF(INDEX(F$21:F$32,MATCH(LARGE(F$36:F$47,1),F$36:F$47,0))=0,"—",INDEX($B$21:$B$32,MATCH(LARGE(F$36:F$47,1),F$36:F$47,0)))) -> — | H8: =IF($D8=0,0,INDEX(F$21:F$32,MATCH(LARGE(F$36:F$47,1),F$36:F$47,0))) -> 0 | I8: =IF($D8=0,"—",IF(INDEX(F$21:F$32,MATCH(LARGE(F$36:F$47,2),F$36:F$47,0))=0,"—",INDEX($B$21:$B$32,MATCH(LARGE(F$36:F$47,2),F$36:F$47,0)))) -> — | J8: =IF($D8=0,0,INDEX(F$21:F$32,MATCH(LARGE(F$36:F$47,2),F$36:F$47,0))) -> 0 | K8: =IF($D8=0,"—",IF(INDEX(F$21:F$32,MATCH(LARGE(F$36:F$47,3),F$36:F$47,0))=0,"—",INDEX($B$21:$B$32,MATCH(LARGE(F$36:F$47,3),F$36:F$47,0)))) -> — | L8: =IF($D8=0,0,INDEX(F$21:F$32,MATCH(LARGE(F$36:F$47,3),F$36:F$47,0))) -> 0
B9: May | C9: ='Monthly Budget'!G10 -> 0 | D9: ='Monthly Budget'!G110 -> 0 | E9: =C9-D9 -> 0 | F9: =IF(C9=0,0,E9/C9) -> 0 | G9: =IF($D9=0,"—",IF(INDEX(G$21:G$32,MATCH(LARGE(G$36:G$47,1),G$36:G$47,0))=0,"—",INDEX($B$21:$B$32,MATCH(LARGE(G$36:G$47,1),G$36:G$47,0)))) -> — | H9: =IF($D9=0,0,INDEX(G$21:G$32,MATCH(LARGE(G$36:G$47,1),G$36:G$47,0))) -> 0 | I9: =IF($D9=0,"—",IF(INDEX(G$21:G$32,MATCH(LARGE(G$36:G$47,2),G$36:G$47,0))=0,"—",INDEX($B$21:$B$32,MATCH(LARGE(G$36:G$47,2),G$36:G$47,0)))) -> — | J9: =IF($D9=0,0,INDEX(G$21:G$32,MATCH(LARGE(G$36:G$47,2),G$36:G$47,0))) -> 0 | K9: =IF($D9=0,"—",IF(INDEX(G$21:G$32,MATCH(LARGE(G$36:G$47,3),G$36:G$47,0))=0,"—",INDEX($B$21:$B$32,MATCH(LARGE(G$36:G$47,3),G$36:G$47,0)))) -> — | L9: =IF($D9=0,0,INDEX(G$21:G$32,MATCH(LARGE(G$36:G$47,3),G$36:G$47,0))) -> 0
B10: Jun | C10: ='Monthly Budget'!H10 -> 0 | D10: ='Monthly Budget'!H110 -> 0 | E10: =C10-D10 -> 0 | F10: =IF(C10=0,0,E10/C10) -> 0 | G10: =IF($D10=0,"—",IF(INDEX(H$21:H$32,MATCH(LARGE(H$36:H$47,1),H$36:H$47,0))=0,"—",INDEX($B$21:$B$32,MATCH(LARGE(H$36:H$47,1),H$36:H$47,0)))) -> — | H10: =IF($D10=0,0,INDEX(H$21:H$32,MATCH(LARGE(H$36:H$47,1),H$36:H$47,0))) -> 0 | I10: =IF($D10=0,"—",IF(INDEX(H$21:H$32,MATCH(LARGE(H$36:H$47,2),H$36:H$47,0))=0,"—",INDEX($B$21:$B$32,MATCH(LARGE(H$36:H$47,2),H$36:H$47,0)))) -> — | J10: =IF($D10=0,0,INDEX(H$21:H$32,MATCH(LARGE(H$36:H$47,2),H$36:H$47,0))) -> 0 | K10: =IF($D10=0,"—",IF(INDEX(H$21:H$32,MATCH(LARGE(H$36:H$47,3),H$36:H$47,0))=0,"—",INDEX($B$21:$B$32,MATCH(LARGE(H$36:H$47,3),H$36:H$47,0)))) -> — | L10: =IF($D10=0,0,INDEX(H$21:H$32,MATCH(LARGE(H$36:H$47,3),H$36:H$47,0))) -> 0
B11: Jul | C11: ='Monthly Budget'!I10 -> 0 | D11: ='Monthly Budget'!I110 -> 0 | E11: =C11-D11 -> 0 | F11: =IF(C11=0,0,E11/C11) -> 0 | G11: =IF($D11=0,"—",IF(INDEX(I$21:I$32,MATCH(LARGE(I$36:I$47,1),I$36:I$47,0))=0,"—",INDEX($B$21:$B$32,MATCH(LARGE(I$36:I$47,1),I$36:I$47,0)))) -> — | H11: =IF($D11=0,0,INDEX(I$21:I$32,MATCH(LARGE(I$36:I$47,1),I$36:I$47,0))) -> 0 | I11: =IF($D11=0,"—",IF(INDEX(I$21:I$32,MATCH(LARGE(I$36:I$47,2),I$36:I$47,0))=0,"—",INDEX($B$21:$B$32,MATCH(LARGE(I$36:I$47,2),I$36:I$47,0)))) -> — | J11: =IF($D11=0,0,INDEX(I$21:I$32,MATCH(LARGE(I$36:I$47,2),I$36:I$47,0))) -> 0 | K11: =IF($D11=0,"—",IF(INDEX(I$21:I$32,MATCH(LARGE(I$36:I$47,3),I$36:I$47,0))=0,"—",INDEX($B$21:$B$32,MATCH(LARGE(I$36:I$47,3),I$36:I$47,0)))) -> — | L11: =IF($D11=0,0,INDEX(I$21:I$32,MATCH(LARGE(I$36:I$47,3),I$36:I$47,0))) -> 0
B12: Aug | C12: ='Monthly Budget'!J10 -> 0 | D12: ='Monthly Budget'!J110 -> 0 | E12: =C12-D12 -> 0 | F12: =IF(C12=0,0,E12/C12) -> 0 | G12: =IF($D12=0,"—",IF(INDEX(J$21:J$32,MATCH(LARGE(J$36:J$47,1),J$36:J$47,0))=0,"—",INDEX($B$21:$B$32,MATCH(LARGE(J$36:J$47,1),J$36:J$47,0)))) -> — | H12: =IF($D12=0,0,INDEX(J$21:J$32,MATCH(LARGE(J$36:J$47,1),J$36:J$47,0))) -> 0 | I12: =IF($D12=0,"—",IF(INDEX(J$21:J$32,MATCH(LARGE(J$36:J$47,2),J$36:J$47,0))=0,"—",INDEX($B$21:$B$32,MATCH(LARGE(J$36:J$47,2),J$36:J$47,0)))) -> — | J12: =IF($D12=0,0,INDEX(J$21:J$32,MATCH(LARGE(J$36:J$47,2),J$36:J$47,0))) -> 0 | K12: =IF($D12=0,"—",IF(INDEX(J$21:J$32,MATCH(LARGE(J$36:J$47,3),J$36:J$47,0))=0,"—",INDEX($B$21:$B$32,MATCH(LARGE(J$36:J$47,3),J$36:J$47,0)))) -> — | L12: =IF($D12=0,0,INDEX(J$21:J$32,MATCH(LARGE(J$36:J$47,3),J$36:J$47,0))) -> 0
B13: Sep | C13: ='Monthly Budget'!K10 -> 0 | D13: ='Monthly Budget'!K110 -> 0 | E13: =C13-D13 -> 0 | F13: =IF(C13=0,0,E13/C13) -> 0 | G13: =IF($D13=0,"—",IF(INDEX(K$21:K$32,MATCH(LARGE(K$36:K$47,1),K$36:K$47,0))=0,"—",INDEX($B$21:$B$32,MATCH(LARGE(K$36:K$47,1),K$36:K$47,0)))) -> — | H13: =IF($D13=0,0,INDEX(K$21:K$32,MATCH(LARGE(K$36:K$47,1),K$36:K$47,0))) -> 0 | I13: =IF($D13=0,"—",IF(INDEX(K$21:K$32,MATCH(LARGE(K$36:K$47,2),K$36:K$47,0))=0,"—",INDEX($B$21:$B$32,MATCH(LARGE(K$36:K$47,2),K$36:K$47,0)))) -> — | J13: =IF($D13=0,0,INDEX(K$21:K$32,MATCH(LARGE(K$36:K$47,2),K$36:K$47,0))) -> 0 | K13: =IF($D13=0,"—",IF(INDEX(K$21:K$32,MATCH(LARGE(K$36:K$47,3),K$36:K$47,0))=0,"—",INDEX($B$21:$B$32,MATCH(LARGE(K$36:K$47,3),K$36:K$47,0)))) -> — | L13: =IF($D13=0,0,INDEX(K$21:K$32,MATCH(LARGE(K$36:K$47,3),K$36:K$47,0))) -> 0
B14: Oct | C14: ='Monthly Budget'!L10 -> 0 | D14: ='Monthly Budget'!L110 -> 0 | E14: =C14-D14 -> 0 | F14: =IF(C14=0,0,E14/C14) -> 0 | G14: =IF($D14=0,"—",IF(INDEX(L$21:L$32,MATCH(LARGE(L$36:L$47,1),L$36:L$47,0))=0,"—",INDEX($B$21:$B$32,MATCH(LARGE(L$36:L$47,1),L$36:L$47,0)))) -> — | H14: =IF($D14=0,0,INDEX(L$21:L$32,MATCH(LARGE(L$36:L$47,1),L$36:L$47,0))) -> 0 | I14: =IF($D14=0,"—",IF(INDEX(L$21:L$32,MATCH(LARGE(L$36:L$47,2),L$36:L$47,0))=0,"—",INDEX($B$21:$B$32,MATCH(LARGE(L$36:L$47,2),L$36:L$47,0)))) -> — | J14: =IF($D14=0,0,INDEX(L$21:L$32,MATCH(LARGE(L$36:L$47,2),L$36:L$47,0))) -> 0 | K14: =IF($D14=0,"—",IF(INDEX(L$21:L$32,MATCH(LARGE(L$36:L$47,3),L$36:L$47,0))=0,"—",INDEX($B$21:$B$32,MATCH(LARGE(L$36:L$47,3),L$36:L$47,0)))) -> — | L14: =IF($D14=0,0,INDEX(L$21:L$32,MATCH(LARGE(L$36:L$47,3),L$36:L$47,0))) -> 0
B15: Nov | C15: ='Monthly Budget'!M10 -> 0 | D15: ='Monthly Budget'!M110 -> 0 | E15: =C15-D15 -> 0 | F15: =IF(C15=0,0,E15/C15) -> 0 | G15: =IF($D15=0,"—",IF(INDEX(M$21:M$32,MATCH(LARGE(M$36:M$47,1),M$36:M$47,0))=0,"—",INDEX($B$21:$B$32,MATCH(LARGE(M$36:M$47,1),M$36:M$47,0)))) -> — | H15: =IF($D15=0,0,INDEX(M$21:M$32,MATCH(LARGE(M$36:M$47,1),M$36:M$47,0))) -> 0 | I15: =IF($D15=0,"—",IF(INDEX(M$21:M$32,MATCH(LARGE(M$36:M$47,2),M$36:M$47,0))=0,"—",INDEX($B$21:$B$32,MATCH(LARGE(M$36:M$47,2),M$36:M$47,0)))) -> — | J15: =IF($D15=0,0,INDEX(M$21:M$32,MATCH(LARGE(M$36:M$47,2),M$36:M$47,0))) -> 0 | K15: =IF($D15=0,"—",IF(INDEX(M$21:M$32,MATCH(LARGE(M$36:M$47,3),M$36:M$47,0))=0,"—",INDEX($B$21:$B$32,MATCH(LARGE(M$36:M$47,3),M$36:M$47,0)))) -> — | L15: =IF($D15=0,0,INDEX(M$21:M$32,MATCH(LARGE(M$36:M$47,3),M$36:M$47,0))) -> 0
B16: Dec | C16: ='Monthly Budget'!N10 -> 0 | D16: ='Monthly Budget'!N110 -> 0 | E16: =C16-D16 -> 0 | F16: =IF(C16=0,0,E16/C16) -> 0 | G16: =IF($D16=0,"—",IF(INDEX(N$21:N$32,MATCH(LARGE(N$36:N$47,1),N$36:N$47,0))=0,"—",INDEX($B$21:$B$32,MATCH(LARGE(N$36:N$47,1),N$36:N$47,0)))) -> — | H16: =IF($D16=0,0,INDEX(N$21:N$32,MATCH(LARGE(N$36:N$47,1),N$36:N$47,0))) -> 0 | I16: =IF($D16=0,"—",IF(INDEX(N$21:N$32,MATCH(LARGE(N$36:N$47,2),N$36:N$47,0))=0,"—",INDEX($B$21:$B$32,MATCH(LARGE(N$36:N$47,2),N$36:N$47,0)))) -> — | J16: =IF($D16=0,0,INDEX(N$21:N$32,MATCH(LARGE(N$36:N$47,2),N$36:N$47,0))) -> 0 | K16: =IF($D16=0,"—",IF(INDEX(N$21:N$32,MATCH(LARGE(N$36:N$47,3),N$36:N$47,0))=0,"—",INDEX($B$21:$B$32,MATCH(LARGE(N$36:N$47,3),N$36:N$47,0)))) -> — | L16: =IF($D16=0,0,INDEX(N$21:N$32,MATCH(LARGE(N$36:N$47,3),N$36:N$47,0))) -> 0
B19: EXPENSE CATEGORY TOTALS — automatic helper table (linked from Monthly Budget; do not type here)
B20: Expense category | C20: JAN | D20: FEB | E20: MAR | F20: APR | G20: MAY | H20: JUN | I20: JUL | J20: AUG | K20: SEP | L20: OCT | M20: NOV | N20: DEC
B21: Home | C21: ='Monthly Budget'!C17 -> 0 | D21: ='Monthly Budget'!D17 -> 0 | E21: ='Monthly Budget'!E17 -> 0 | F21: ='Monthly Budget'!F17 -> 0 | G21: ='Monthly Budget'!G17 -> 0 | H21: ='Monthly Budget'!H17 -> 0 | I21: ='Monthly Budget'!I17 -> 0 | J21: ='Monthly Budget'!J17 -> 0 | ... N21: ='Monthly Budget'!N17 -> 0
B22: Daily Living | C22: ='Monthly Budget'!C26 -> 0 | D22: ='Monthly Budget'!D26 -> 0 | E22: ='Monthly Budget'!E26 -> 0 | F22: ='Monthly Budget'!F26 -> 0 | G22: ='Monthly Budget'!G26 -> 0 | H22: ='Monthly Budget'!H26 -> 0 | I22: ='Monthly Budget'!I26 -> 0 | J22: ='Monthly Budget'!J26 -> 0 | ... N22: ='Monthly Budget'!N26 -> 0
B23: Transportation | C23: ='Monthly Budget'!C35 -> 0 | D23: ='Monthly Budget'!D35 -> 0 | E23: ='Monthly Budget'!E35 -> 0 | F23: ='Monthly Budget'!F35 -> 0 | G23: ='Monthly Budget'!G35 -> 0 | H23: ='Monthly Budget'!H35 -> 0 | I23: ='Monthly Budget'!I35 -> 0 | J23: ='Monthly Budget'!J35 -> 0 | ... N23: ='Monthly Budget'!N35 -> 0
B24: Entertainment | C24: ='Monthly Budget'!C42 -> 0 | D24: ='Monthly Budget'!D42 -> 0 | E24: ='Monthly Budget'!E42 -> 0 | F24: ='Monthly Budget'!F42 -> 0 | G24: ='Monthly Budget'!G42 -> 0 | H24: ='Monthly Budget'!H42 -> 0 | I24: ='Monthly Budget'!I42 -> 0 | J24: ='Monthly Budget'!J42 -> 0 | ... N24: ='Monthly Budget'!N42 -> 0
B25: Health | C25: ='Monthly Budget'!C52 -> 0 | D25: ='Monthly Budget'!D52 -> 0 | E25: ='Monthly Budget'!E52 -> 0 | F25: ='Monthly Budget'!F52 -> 0 | G25: ='Monthly Budget'!G52 -> 0 | H25: ='Monthly Budget'!H52 -> 0 | I25: ='Monthly Budget'!I52 -> 0 | J25: ='Monthly Budget'!J52 -> 0 | ... N25: ='Monthly Budget'!N52 -> 0
B26: Vacations | C26: ='Monthly Budget'!C61 -> 0 | D26: ='Monthly Budget'!D61 -> 0 | E26: ='Monthly Budget'!E61 -> 0 | F26: ='Monthly Budget'!F61 -> 0 | G26: ='Monthly Budget'!G61 -> 0 | H26: ='Monthly Budget'!H61 -> 0 | I26: ='Monthly Budget'!I61 -> 0 | J26: ='Monthly Budget'!J61 -> 0 | ... N26: ='Monthly Budget'!N61 -> 0
B27: Recreation | C27: ='Monthly Budget'!C68 -> 0 | D27: ='Monthly Budget'!D68 -> 0 | E27: ='Monthly Budget'!E68 -> 0 | F27: ='Monthly Budget'!F68 -> 0 | G27: ='Monthly Budget'!G68 -> 0 | H27: ='Monthly Budget'!H68 -> 0 | I27: ='Monthly Budget'!I68 -> 0 | J27: ='Monthly Budget'!J68 -> 0 | ... N27: ='Monthly Budget'!N68 -> 0
B28: Dues & Subscriptions | C28: ='Monthly Budget'!C77 -> 0 | D28: ='Monthly Budget'!D77 -> 0 | E28: ='Monthly Budget'!E77 -> 0 | F28: ='Monthly Budget'!F77 -> 0 | G28: ='Monthly Budget'!G77 -> 0 | H28: ='Monthly Budget'!H77 -> 0 | I28: ='Monthly Budget'!I77 -> 0 | J28: ='Monthly Budget'!J77 -> 0 | ... N28: ='Monthly Budget'!N77 -> 0
B29: Personal | C29: ='Monthly Budget'!C85 -> 0 | D29: ='Monthly Budget'!D85 -> 0 | E29: ='Monthly Budget'!E85 -> 0 | F29: ='Monthly Budget'!F85 -> 0 | G29: ='Monthly Budget'!G85 -> 0 | H29: ='Monthly Budget'!H85 -> 0 | I29: ='Monthly Budget'!I85 -> 0 | J29: ='Monthly Budget'!J85 -> 0 | ... N29: ='Monthly Budget'!N85 -> 0
B30: Financial Obligations | C30: ='Monthly Budget'!C98 -> 0 | D30: ='Monthly Budget'!D98 -> 0 | E30: ='Monthly Budget'!E98 -> 0 | F30: ='Monthly Budget'!F98 -> 0 | G30: ='Monthly Budget'!G98 -> 0 | H30: ='Monthly Budget'!H98 -> 0 | I30: ='Monthly Budget'!I98 -> 0 | J30: ='Monthly Budget'!J98 -> 0 | ... N30: ='Monthly Budget'!N98 -> 0
B31: Miscellaneous Payments | C31: ='Monthly Budget'!C107 -> 0 | D31: ='Monthly Budget'!D107 -> 0 | E31: ='Monthly Budget'!E107 -> 0 | F31: ='Monthly Budget'!F107 -> 0 | G31: ='Monthly Budget'!G107 -> 0 | H31: ='Monthly Budget'!H107 -> 0 | I31: ='Monthly Budget'!I107 -> 0 | J31: ='Monthly Budget'!J107 -> 0 | ... N31: ='Monthly Budget'!N107 -> 0
B34: TOP-3 TIE-BREAK HELPER — automatic; adds less than one cent behind the scenes so equal categories never repeat in the Top 3
B35: Expense category | C35: JAN | D35: FEB | E35: MAR | F35: APR | G35: MAY | H35: JUN | I35: JUL | J35: AUG | K35: SEP | L35: OCT | M35: NOV | N35: DEC
B36: Home | C36: =C21+(ROW()-35)/1000000 -> 1e-06 | D36: =D21+(ROW()-35)/1000000 -> 1e-06 | E36: =E21+(ROW()-35)/1000000 -> 1e-06 | F36: =F21+(ROW()-35)/1000000 -> 1e-06 | G36: =G21+(ROW()-35)/1000000 -> 1e-06 | H36: =H21+(ROW()-35)/1000000 -> 1e-06 | I36: =I21+(ROW()-35)/1000000 -> 1e-06 | J36: =J21+(ROW()-35)/1000000 -> 1e-06 | ... N36: =N21+(ROW()-35)/1000000 -> 1e-06
B37: Daily Living | C37: =C22+(ROW()-35)/1000000 -> 2e-06 | D37: =D22+(ROW()-35)/1000000 -> 2e-06 | E37: =E22+(ROW()-35)/1000000 -> 2e-06 | F37: =F22+(ROW()-35)/1000000 -> 2e-06 | G37: =G22+(ROW()-35)/1000000 -> 2e-06 | H37: =H22+(ROW()-35)/1000000 -> 2e-06 | I37: =I22+(ROW()-35)/1000000 -> 2e-06 | J37: =J22+(ROW()-35)/1000000 -> 2e-06 | ... N37: =N22+(ROW()-35)/1000000 -> 2e-06
B38: Transportation | C38: =C23+(ROW()-35)/1000000 -> 3e-06 | D38: =D23+(ROW()-35)/1000000 -> 3e-06 | E38: =E23+(ROW()-35)/1000000 -> 3e-06 | F38: =F23+(ROW()-35)/1000000 -> 3e-06 | G38: =G23+(ROW()-35)/1000000 -> 3e-06 | H38: =H23+(ROW()-35)/1000000 -> 3e-06 | I38: =I23+(ROW()-35)/1000000 -> 3e-06 | J38: =J23+(ROW()-35)/1000000 -> 3e-06 | ... N38: =N23+(ROW()-35)/1000000 -> 3e-06
B39: Entertainment | C39: =C24+(ROW()-35)/1000000 -> 4e-06 | D39: =D24+(ROW()-35)/1000000 -> 4e-06 | E39: =E24+(ROW()-35)/1000000 -> 4e-06 | F39: =F24+(ROW()-35)/1000000 -> 4e-06 | G39: =G24+(ROW()-35)/1000000 -> 4e-06 | H39: =H24+(ROW()-35)/1000000 -> 4e-06 | I39: =I24+(ROW()-35)/1000000 -> 4e-06 | J39: =J24+(ROW()-35)/1000000 -> 4e-06 | ... N39: =N24+(ROW()-35)/1000000 -> 4e-06
B40: Health | C40: =C25+(ROW()-35)/1000000 -> 5e-06 | D40: =D25+(ROW()-35)/1000000 -> 5e-06 | E40: =E25+(ROW()-35)/1000000 -> 5e-06 | F40: =F25+(ROW()-35)/1000000 -> 5e-06 | G40: =G25+(ROW()-35)/1000000 -> 5e-06 | H40: =H25+(ROW()-35)/1000000 -> 5e-06 | I40: =I25+(ROW()-35)/1000000 -> 5e-06 | J40: =J25+(ROW()-35)/1000000 -> 5e-06 | ... N40: =N25+(ROW()-35)/1000000 -> 5e-06
B41: Vacations | C41: =C26+(ROW()-35)/1000000 -> 6e-06 | D41: =D26+(ROW()-35)/1000000 -> 6e-06 | E41: =E26+(ROW()-35)/1000000 -> 6e-06 | F41: =F26+(ROW()-35)/1000000 -> 6e-06 | G41: =G26+(ROW()-35)/1000000 -> 6e-06 | H41: =H26+(ROW()-35)/1000000 -> 6e-06 | I41: =I26+(ROW()-35)/1000000 -> 6e-06 | J41: =J26+(ROW()-35)/1000000 -> 6e-06 | ... N41: =N26+(ROW()-35)/1000000 -> 6e-06
B42: Recreation | C42: =C27+(ROW()-35)/1000000 -> 7e-06 | D42: =D27+(ROW()-35)/1000000 -> 7e-06 | E42: =E27+(ROW()-35)/1000000 -> 7e-06 | F42: =F27+(ROW()-35)/1000000 -> 7e-06 | G42: =G27+(ROW()-35)/1000000 -> 7e-06 | H42: =H27+(ROW()-35)/1000000 -> 7e-06 | I42: =I27+(ROW()-35)/1000000 -> 7e-06 | J42: =J27+(ROW()-35)/1000000 -> 7e-06 | ... N42: =N27+(ROW()-35)/1000000 -> 7e-06
B43: Dues & Subscriptions | C43: =C28+(ROW()-35)/1000000 -> 8e-06 | D43: =D28+(ROW()-35)/1000000 -> 8e-06 | E43: =E28+(ROW()-35)/1000000 -> 8e-06 | F43: =F28+(ROW()-35)/1000000 -> 8e-06 | G43: =G28+(ROW()-35)/1000000 -> 8e-06 | H43: =H28+(ROW()-35)/1000000 -> 8e-06 | I43: =I28+(ROW()-35)/1000000 -> 8e-06 | J43: =J28+(ROW()-35)/1000000 -> 8e-06 | ... N43: =N28+(ROW()-35)/1000000 -> 8e-06
B44: Personal | C44: =C29+(ROW()-35)/1000000 -> 9e-06 | D44: =D29+(ROW()-35)/1000000 -> 9e-06 | E44: =E29+(ROW()-35)/1000000 -> 9e-06 | F44: =F29+(ROW()-35)/1000000 -> 9e-06 | G44: =G29+(ROW()-35)/1000000 -> 9e-06 | H44: =H29+(ROW()-35)/1000000 -> 9e-06 | I44: =I29+(ROW()-35)/1000000 -> 9e-06 | J44: =J29+(ROW()-35)/1000000 -> 9e-06 | ... N44: =N29+(ROW()-35)/1000000 -> 9e-06
B45: Financial Obligations | C45: =C30+(ROW()-35)/1000000 -> 1e-05 | D45: =D30+(ROW()-35)/1000000 -> 1e-05 | E45: =E30+(ROW()-35)/1000000 -> 1e-05 | F45: =F30+(ROW()-35)/1000000 -> 1e-05 | G45: =G30+(ROW()-35)/1000000 -> 1e-05 | H45: =H30+(ROW()-35)/1000000 -> 1e-05 | I45: =I30+(ROW()-35)/1000000 -> 1e-05 | J45: =J30+(ROW()-35)/1000000 -> 1e-05 | ... N45: =N30+(ROW()-35)/1000000 -> 1e-05
...
